Workbook
Name Austragungsort: Allgemeines!$B$2
Name date: Allgemeines!$B$4
Name Datum: Allgemeines!$B$4
Name Gruppe: Allgemeines!$B$1
Name Ort: Allgemeines!$B$3
Name Team1: Allgemeines!$B$7
Name Team2: Allgemeines!$B$8
Name Team3: Allgemeines!$B$9
Name Team4: Allgemeines!$B$10
Name Team5: Allgemeines!$B$11
Name Team6: Allgemeines!$B$12

Sheet Allgemeines
A1: Gruppe | B1: II | D1: Gruppenkoordinator:in | G1: von | H1: bis
A2: Austragungsort | B2: Sporthalle Berlin | D2: George Washington | F2: 1.Begegnung | G2: 0.375 | H2: =G2+1.5/24 -> 0.4375
A3: Ort | B3: Hamburg | F3: 2.Begegnung | G3: =H2 -> 0.4375 | H3: =G3+1.5/24 -> 0.5
A4: Datum | B4: 46023 | F4: 3.Begegnung | G4: =H3+0.5/24 -> 0.52083333 | H4: =G4+1.5/24 -> 0.58333333
F5: 4.Begegnung | G5: =H4 -> 0.58333333 | H5: =G5+1.5/24 -> 0.64583333
B6: Teamname | D6: Kapitän:in | F6: 5.Begegnung | G6: =H5 -> 0.64583333 | H6: =G6+1.5/24 -> 0.70833333
A7: Team 1 | B7: A-Team | D7: Adele
A8: Team 2 | B8: B-Team | D8: Barack Obama
A9: Team 3 | B9: C-Team | D9: Coco Chanel | G9: Format für die Uhrzeit:
A10: Team 4 | B10: D-Team | D10: Diego Maradona | G10: ##:##
A11: Team 5 | B11: E-Team | D11: Eva Mendes | G11: wo # eine Zahl ist
A12: Team 6 | B12: F-Team | D12: Freddy Mercury

Sheet Setzlisten
A1: Team 1 | B1: =Team1 -> A-Team
C2: Vorname oder Alias | D2: Nachname
A3: =CONCATENATE(Team1," ",B3) -> A-Team 1 | B3: 1 | C3: Albert | D3: Einstein | E3: =IF(C3="","",IF(D3="",C3,CONCATENATE(C3," ",D3))) -> Albert Einstein
A4: =CONCATENATE(Team1," ",B4) -> A-Team 2 | B4: 2 | C4: Angela | D4: Merkel | E4: =IF(C4="","",IF(D4="",C4,CONCATENATE(C4," ",D4))) -> Angela Merkel
A5: =CONCATENATE(Team1," ",B5) -> A-Team 3 | B5: 3 | C5: Adele | E5: =IF(C5="","",IF(D5="",C5,CONCATENATE(C5," ",D5))) -> Adele
A6: =CONCATENATE(Team1," ",B6) -> A-Team 4 | B6: 4 | C6: Arnold Schwarzenegger | E6: =IF(C6="","",IF(D6="",C6,CONCATENATE(C6," ",D6))) -> Arnold Schwarzenegger
A7: =CONCATENATE(Team1," ",B7) -> A-Team 5 | B7: 5 | C7: Alexander | D7: Graham Bell | E7: =IF(C7="","",IF(D7="",C7,CONCATENATE(C7," ",D7))) -> Alexander Graham Bell
A8: =CONCATENATE(Team1," ",B8) -> A-Team 6 | B8: 6 | C8: Amelia | D8: Earhart | E8: =IF(C8="","",IF(D8="",C8,CONCATENATE(C8," ",D8))) -> Amelia Earhart
A9: =CONCATENATE(Team1," ",B9) -> A-Team 7 | B9: 7 | C9: Anne | D9: Frank | E9: =IF(C9="","",IF(D9="",C9,CONCATENATE(C9," ",D9))) -> Anne Frank
A10: =CONCATENATE(Team1," ",B10) -> A-Team 8 | B10: 8 | C10: Audrey | D10: Hepburn | E10: =IF(C10="","",IF(D10="",C10,CONCATENATE(C10," ",D10))) -> Audrey Hepburn
A11: =CONCATENATE(Team1," ",B11) -> A-Team 9 | B11: 9 | E11: =IF(C11="","",IF(D11="",C11,CONCATENATE(C11," ",D11)))
A12: =CONCATENATE(Team1," ",B12) -> A-Team 10 | B12: 10 | E12: =IF(C12="","",IF(D12="",C12,CONCATENATE(C12," ",D12)))
A13: =CONCATENATE(Team1," ",B13) -> A-Team 11 | B13: 11 | E13: =IF(C13="","",IF(D13="",C13,CONCATENATE(C13," ",D13)))
A14: =CONCATENATE(Team1," ",B14) -> A-Team 12 | B14: 12 | E14: =IF(C14="","",IF(D14="",C14,CONCATENATE(C14," ",D14)))
A15: =CONCATENATE(Team1," ",B15) -> A-Team 13 | B15: 13 | E15: =IF(C15="","",IF(D15="",C15,CONCATENATE(C15," ",D15)))
A16: =CONCATENATE(Team1," ",B16) -> A-Team 14 | B16: 14 | E16: =IF(C16="","",IF(D16="",C16,CONCATENATE(C16," ",D16)))
A17: =CONCATENATE(Team1," ",B17) -> A-Team 15 | B17: 15 | E17: =IF(C17="","",IF(D17="",C17,CONCATENATE(C17," ",D17)))
A19: Team 2 | B19: =Team2 -> B-Team
C20: Vorname oder Alias | D20: Nachname
A21: =CONCATENATE(Team2," ",B21) -> B-Team 1 | B21: 1 | C21: Barack | D21: Obama | E21: =IF(C21="","",IF(D21="",C21,CONCATENATE(C21," ",D21))) -> Barack Obama
A22: =CONCATENATE(Team2," ",B22) -> B-Team 2 | B22: 2 | C22: Beyoncé | E22: =IF(C22="","",IF(D22="",C22,CONCATENATE(C22," ",D22))) -> Beyoncé
A23: =CONCATENATE(Team2," ",B23) -> B-Team 3 | B23: 3 | C23: Brad Pitt | E23: =IF(C23="","",IF(D23="",C23,CONCATENATE(C23," ",D23))) -> Brad Pitt
A24: =CONCATENATE(Team2," ",B24) -> B-Team 4 | B24: 4 | C24: Boris | D24: Becker | E24: =IF(C24="","",IF(D24="",C24,CONCATENATE(C24," ",D24))) -> Boris Becker
A25: =CONCATENATE(Team2," ",B25) -> B-Team 5 | B25: 5 | C25: Bill | D25: Gates | E25: =IF(C25="","",IF(D25="",C25,CONCATENATE(C25," ",D25))) -> Bill Gates
A26: =CONCATENATE(Team2," ",B26) -> B-Team 6 | B26: 6 | C26: Bob | D26: Marley | E26: =IF(C26="","",IF(D26="",C26,CONCATENATE(C26," ",D26))) -> Bob Marley
A27: =CONCATENATE(Team2," ",B27) -> B-Team 7 | B27: 7 | C27: Brigitte | D27: Bardot | E27: =IF(C27="","",IF(D27="",C27,CONCATENATE(C27," ",D27))) -> Brigitte Bardot
A28: =CONCATENATE(Team2," ",B28) -> B-Team 8 | B28: 8 | C28: Bruce | D28: Willis | E28: =IF(C28="","",IF(D28="",C28,CONCATENATE(C28," ",D28))) -> Bruce Willis
A29: =CONCATENATE(Team2," ",B29) -> B-Team 9 | B29: 9 | E29: =IF(C29="","",IF(D29="",C29,CONCATENATE(C29," ",D29)))
A30: =CONCATENATE(Team2," ",B30) -> B-Team 10 | B30: 10 | E30: =IF(C30="","",IF(D30="",C30,CONCATENATE(C30," ",D30)))
A31: =CONCATENATE(Team2," ",B31) -> B-Team 11 | B31: 11 | E31: =IF(C31="","",IF(D31="",C31,CONCATENATE(C31," ",D31)))
A32: =CONCATENATE(Team2," ",B32) -> B-Team 12 | B32: 12 | E32: =IF(C32="","",IF(D32="",C32,CONCATENATE(C32," ",D32)))
A33: =CONCATENATE(Team2," ",B33) -> B-Team 13 | B33: 13 | E33: =IF(C33="","",IF(D33="",C33,CONCATENATE(C33," ",D33)))
A34: =CONCATENATE(Team2," ",B34) -> B-Team 14 | B34: 14 | E34: =IF(C34="","",IF(D34="",C34,CONCATENATE(C34," ",D34)))
A35: =CONCATENATE(Team2," ",B35) -> B-Team 15 | B35: 15 | E35: =IF(C35="","",IF(D35="",C35,CONCATENATE(C35," ",D35)))
A37: Team 3 | B37: =Team3 -> C-Team
C38: Vorname oder Alias | D38: Nachname
A39: =CONCATENATE(Team3," ",B39) -> C-Team 1 | B39: 1 | C39: Christiano | D39: Ronaldo | E39: =IF(C39="","",IF(D39="",C39,CONCATENATE(C39," ",D39))) -> Christiano Ronaldo
A40: =CONCATENATE(Team3," ",B40) -> C-Team 2 | B40: 2 | C40: Celine | D40: Dion | E40: =IF(C40="","",IF(D40="",C40,CONCATENATE(C40," ",D40))) -> Celine Dion
A41: =CONCATENATE(Team3," ",B41) -> C-Team 3 | B41: 3 | C41: Charlie | D41: Chaplin | E41: =IF(C41="","",IF(D41="",C41,CONCATENATE(C41," ",D41))) -> Charlie Chaplin
A42: =CONCATENATE(Team3," ",B42) -> C-Team 4 | B42: 4 | C42: Clint | D42: Eastwood | E42: =IF(C42="","",IF(D42="",C42,CONCATENATE(C42," ",D42))) -> Clint Eastwood
...

Sheet 1.Begegnung
A1: Queere Badminton Liga | F1: =IF(V12>V14,CONCATENATE("Achtung! Teamreihenfolge ",D5," nicht richtig! 1. und 2. Doppel tauschen."),IF(V14>V16,CONCATENATE("Achtung! Teamreihenfolge ",D5," nicht richtig! 2. und 3. Doppel tauschen."),IF(AND(V18>=V19,V19>0),CONCATENATE("Achtung! Teamreihenfolge ",D5," nicht richtig! Beide Einzel tauschen."),IF(W12>W14,CONCATENATE("Achtung! Teamreihenfolge ",D7," nicht richtig! 1. und 2. Doppel tauschen."),IF(W14>W16,CONCATENATE("Achtung! Teamreihenfolge ",D7," nicht richtig! 2. und 3. Doppel tauschen."),IF(AND(W18>=W19,W19>0),CONCATENATE("Achtung! Teamreihenfolge ",D7," nicht richtig! Beide Einzel tauschen."),""))))))
A2: Spielberichtsbogen
A3: Match Report Sheet
A5: Heimteam: | L5: Gruppe: | M5: =Gruppe -> II
C6: Home team | L6: Group
A7: Gastteam: | J7: Austragungsort: | M7: =Austragungsort -> Sporthalle Berlin | Y7: Heimteam | AA7: Gastteam | AD7: Text für meinspielplan.de
C8: Guest team | L8: Venue | Y8: 1 | Z8: =VLOOKUP(CONCATENATE($D5," ",Y8),Setzlisten!$A:$E,5,0) -> #N/A | AA8: =VLOOKUP(CONCATENATE($D7," ",Y8),Setzlisten!$A:$E,5,0) -> #N/A | AB8: 1 | AD8: =CONCATENATE(A12,": ",D12," mit ",D13," - ",G12," mit ",G13,", ",I12,":",J12,", ",K12,":",L12,IF(M12="","",CONCATENATE(", ",M12,":",N12)),CHAR(10),A14,": ",D14," mit ",D15," - ",G14," mit ",G15,", ",I14,":",J14,", ",K14,":",L14,IF(M14="","",CONCATENATE(", ",M14,":",N14)),CHAR(10),A16,": ",D16," mit ",D17," - ",G16," mit ",G17,", ",I16,":",J16,", ",K16,":",L16,IF(M16="","",CONCATENATE(", ",M16,":",N16)),CHAR(10),A18,": ",D18," - ",G18,", ",I18,":",J18,", ",K18,":",L18,IF(M18="","",CONCATENATE(", ",M18,":",N18)),CHAR(10),A19,": ",D19," - ",G19,", ",I19,":",J19,", ",K19,":",L19,IF(M19="","",CONCATENATE(", ",M19,":",N19))) -> 1. Doppel 1st Doubles: mit - mit , :, : 2. Doppel 2nd Doubles: mit - mit , :, : 3. Doppel 3rd Doubles: mit - mit , :, : 1. Einzel 1st Singles: - , :, : 2. Einzel 2nd Singles: - , :, :
A9: Beginn: (Start) | C9: RL-Pos. | D9: Heimteam Home team | F9: RL-Pos. | G9: Gastteam Guest team | I9: 1. Satz 1st Game | K9: 2. Satz 2nd Game | M9: 3. Satz 3rd Game | O9: Punkte (Points) | Q9: Sätze (Games) | S9: Spiele (Matches) | V9: RL-Pos. Heim-team | W9: RL-Pos. Gast-team | Y9: 2 | Z9: =VLOOKUP(CONCATENATE($D5," ",Y9),Setzlisten!$A:$E,5,0) -> #N/A | AA9: =VLOOKUP(CONCATENATE($D7," ",Y9),Setzlisten!$A:$E,5,0) -> #N/A | AB9: 2
A10: =Allgemeines!G2 -> 0.375 | O10: Heim Home | P10: Gast Guest | Q10: Heim Home | R10: Gast Guest | S10: Heim Home | T10: Gast Guest | Y10: 3 | Z10: =VLOOKUP(CONCATENATE($D5," ",Y10),Setzlisten!$A:$E,5,0) -> #N/A | AA10: =VLOOKUP(CONCATENATE($D7," ",Y10),Setzlisten!$A:$E,5,0) -> #N/A | AB10: 3
Y11: 4 | Z11: =VLOOKUP(CONCATENATE($D5," ",Y11),Setzlisten!$A:$E,5,0) -> #N/A | AA11: =VLOOKUP(CONCATENATE($D7," ",Y11),Setzlisten!$A:$E,5,0) -> #N/A | AB11: 4
A12: 1. Doppel 1st Doubles | C12: =IF(D12="",0,VLOOKUP(D12,$Z8:$AB22,3,0)) -> 0 | F12: =IF(G12="",0,VLOOKUP(G12,$AA8:$AB22,2,0)) -> 0 | O12: =IF(I12="","",SUM(I12,K12,M12)) | P12: =IF(J12="","",SUM(J12,L12,N12)) | Q12: =IF(I12="","",IF(I12>J12,1,0)+IF(K12>L12,1,0)+IF(M12="",0,IF(M12>N12,1,0))) | R12: =IF(I12="","",IF(J12>I12,1,0)+IF(L12>K12,1,0)+IF(M12="",0,IF(N12>M12,1,0))) | S12: =IF(I12="","",IF(Q12>R12,1,0)) | T12: =IF(I12="","",IF(R12>Q12,1,0)) | V12: =C12+C13 -> 0 | W12: =F12+F13 -> 0 | Y12: 5 | Z12: =VLOOKUP(CONCATENATE($D5," ",Y12),Setzlisten!$A:$E,5,0) -> #N/A | AA12: =VLOOKUP(CONCATENATE($D7," ",Y12),Setzlisten!$A:$E,5,0) -> #N/A | AB12: 5
C13: =IF(D13="",0,VLOOKUP(D13,$Z8:$AB22,3,0)) -> 0 | F13: =IF(G13="",0,VLOOKUP(G13,$AA8:$AB22,2,0)) -> 0 | Y13: 6 | Z13: =VLOOKUP(CONCATENATE($D5," ",Y13),Setzlisten!$A:$E,5,0) -> #N/A | AA13: =VLOOKUP(CONCATENATE($D7," ",Y13),Setzlisten!$A:$E,5,0) -> #N/A | AB13: 6
A14: 2. Doppel 2nd Doubles | C14: =IF(D14="",0,VLOOKUP(D14,$Z8:$AB22,3,0)) -> 0 | F14: =IF(G14="",0,VLOOKUP(G14,$AA8:$AB22,2,0)) -> 0 | O14: =IF(I14="","",SUM(I14,K14,M14)) | P14: =IF(J14="","",SUM(J14,L14,N14)) | Q14: =IF(I14="","",IF(I14>J14,1,0)+IF(K14>L14,1,0)+IF(M14="",0,IF(M14>N14,1,0))) | R14: =IF(I14="","",IF(J14>I14,1,0)+IF(L14>K14,1,0)+IF(M14="",0,IF(N14>M14,1,0))) | S14: =IF(I14="","",IF(Q14>R14,1,0)) | T14: =IF(I14="","",IF(R14>Q14,1,0)) | V14: =C14+C15 -> 0 | W14: =F14+F15 -> 0 | Y14: 7 | Z14: =VLOOKUP(CONCATENATE($D5," ",Y14),Setzlisten!$A:$E,5,0) -> #N/A | AA14: =VLOOKUP(CONCATENATE($D7," ",Y14),Setzlisten!$A:$E,5,0) -> #N/A | AB14: 7 | AD14: ↑ Zelle kopieren ↓ nur "Werte" unten einfügen
C15: =IF(D15="",0,VLOOKUP(D15,$Z8:$AB22,3,0)) -> 0 | F15: =IF(G15="",0,VLOOKUP(G15,$AA8:$AB22,2,0)) -> 0 | Y15: 8 | Z15: =VLOOKUP(CONCATENATE($D5," ",Y15),Setzlisten!$A:$E,5,0) -> #N/A | AA15: =VLOOKUP(CONCATENATE($D7," ",Y15),Setzlisten!$A:$E,5,0) -> #N/A | AB15: 8
A16: 3. Doppel 3rd Doubles | C16: =IF(D16="",0,VLOOKUP(D16,$Z8:$AB22,3,0)) -> 0 | F16: =IF(G16="",0,VLOOKUP(G16,$AA8:$AB22,2,0)) -> 0 | O16: =IF(I16="","",SUM(I16,K16,M16)) | P16: =IF(J16="","",SUM(J16,L16,N16)) | Q16: =IF(I16="","",IF(I16>J16,1,0)+IF(K16>L16,1,0)+IF(M16="",0,IF(M16>N16,1,0))) | R16: =IF(I16="","",IF(J16>I16,1,0)+IF(L16>K16,1,0)+IF(M16="",0,IF(N16>M16,1,0))) | S16: =IF(I16="","",IF(Q16>R16,1,0)) | T16: =IF(I16="","",IF(R16>Q16,1,0)) | V16: =C16+C17 -> 0 | W16: =F16+F17 -> 0 | Y16: 9 | Z16: =VLOOKUP(CONCATENATE($D5," ",Y16),Setzlisten!$A:$E,5,0) -> #N/A | AA16: =VLOOKUP(CONCATENATE($D7," ",Y16),Setzlisten!$A:$E,5,0) -> #N/A | AB16: 9
C17: =IF(D17="",0,VLOOKUP(D17,$Z8:$AB22,3,0)) -> 0 | F17: =IF(G17="",0,VLOOKUP(G17,$AA8:$AB22,2,0)) -> 0 | Y17: 10 | Z17: =VLOOKUP(CONCATENATE($D5," ",Y17),Setzlisten!$A:$E,5,0) -> #N/A | AA17: =VLOOKUP(CONCATENATE($D7," ",Y17),Setzlisten!$A:$E,5,0) -> #N/A | AB17: 10
A18: 1. Einzel 1st Singles | C18: =IF(D18="",0,VLOOKUP(D18,$Z8:$AB22,3,0)) -> 0 | F18: =IF(G18="",0,VLOOKUP(G18,$AA8:$AB22,2,0)) -> 0 | O18: =IF(I18="","",SUM(I18,K18,M18)) | P18: =IF(J18="","",SUM(J18,L18,N18)) | Q18: =IF(I18="","",IF(I18>J18,1,0)+IF(K18>L18,1,0)+IF(M18="",0,IF(M18>N18,1,0))) | R18: =IF(I18="","",IF(J18>I18,1,0)+IF(L18>K18,1,0)+IF(M18="",0,IF(N18>M18,1,0))) | S18: =IF(I18="","",IF(Q18>R18,1,0)) | T18: =IF(I18="","",IF(R18>Q18,1,0)) | V18: =C18 -> 0 | W18: =F18 -> 0 | Y18: 11 | Z18: =VLOOKUP(CONCATENATE($D5," ",Y18),Setzlisten!$A:$E,5,0) -> #N/A | AA18: =VLOOKUP(CONCATENATE($D7," ",Y18),Setzlisten!$A:$E,5,0) -> #N/A | AB18: 11
A19: 2. Einzel 2nd Singles | C19: =IF(D19="",0,VLOOKUP(D19,$Z8:$AB22,3,0)) -> 0 | F19: =IF(G19="",0,VLOOKUP(G19,$AA8:$AB22,2,0)) -> 0 | O19: =IF(I19="","",SUM(I19,K19,M19)) | P19: =IF(J19="","",SUM(J19,L19,N19)) | Q19: =IF(I19="","",IF(I19>J19,1,0)+IF(K19>L19,1,0)+IF(M19="",0,IF(M19>N19,1,0))) | R19: =IF(I19="","",IF(J19>I19,1,0)+IF(L19>K19,1,0)+IF(M19="",0,IF(N19>M19,1,0))) | S19: =IF(I19="","",IF(Q19>R19,1,0)) | T19: =IF(I19="","",IF(R19>Q19,1,0)) | V19: =C19 -> 0 | W19: =F19 -> 0 | Y19: 12 | Z19: =VLOOKUP(CONCATENATE($D5," ",Y19),Setzlisten!$A:$E,5,0) -> #N/A | AA19: =VLOOKUP(CONCATENATE($D7," ",Y19),Setzlisten!$A:$E,5,0) -> #N/A | AB19: 12
Y20: 13 | Z20: =VLOOKUP(CONCATENATE($D5," ",Y20),Setzlisten!$A:$E,5,0) -> #N/A | AA20: =VLOOKUP(CONCATENATE($D7," ",Y20),Setzlisten!$A:$E,5,0) -> #N/A | AB20: 13
A21: Ende (End): | C21: Sieger: Winner | E21: =IF(S21="","",IF(S21>T21,D5,D7)) | I21: Ergebnis: Result | O21: =IF(O12="","",SUM(O12:O19)) | P21: =IF(P12="","",SUM(P12:P19)) | Q21: =IF(Q12="","",SUM(Q12:Q19)) | R21: =IF(R12="","",SUM(R12:R19)) | S21: =IF(S12="","",SUM(S12:S19)) | T21: =IF(T12="","",SUM(T12:T19)) | Y21: 14 | Z21: =VLOOKUP(CONCATENATE($D5," ",Y21),Setzlisten!$A:$E,5,0) -> #N/A | AA21: =VLOOKUP(CONCATENATE($D7," ",Y21),Setzlisten!$A:$E,5,0) -> #N/A | AB21: 14
A22: =Allgemeines!H2 -> 0.4375 | Y22: 15 | Z22: =VLOOKUP(CONCATENATE($D5," ",Y22),Setzlisten!$A:$E,5,0) -> #N/A | AA22: =VLOOKUP(CONCATENATE($D7," ",Y22),Setzlisten!$A:$E,5,0) -> #N/A | AB22: 15
D24: Besondere Vorkommnisse: Noteworthy Events
A26: Die Richtigkeit der Angaben wird bescheinigt. Das Spiel hat unter Beachtung der Spielordnung stattgefunden. The accuracy of the information is certified. The match took place in accordance with the League and Match Rules.
A27: =Allgemeines!$B$3 -> Hamburg | E27: =Allgemeines!$B$4 -> 46023
A29: Ort (Place) | E29: Datum (Date) | G29: Gruppenkoordinator:in | J29: Kapitän:in Heimverein | P29: Kapitän:in Gastverein
G30: Group Coordinator | J30: Captain Home Club | P30: Captain Guest Club
G31: =Allgemeines!$D$2 -> George Washington | J31: =IF(D5="","",VLOOKUP(D5,Allgemeines!$B$7:$D$12,3,0)) | P31: =IF(D7="","",VLOOKUP(D7,Allgemeines!$B$7:$D$12,3,0))
A32: Queere Badminton Liga | F32: =IF(V43>V45,CONCATENATE("Achtung! Teamreihenfolge ",D36," nicht richtig! 1. und 2. Doppel tauschen."),IF(V45>V47,CONCATENATE("Achtung! Teamreihenfolge ",D36," nicht richtig! 2. und 3. Doppel tauschen."),IF(AND(V49>=V50,V50>0),CONCATENATE("Achtung! Teamreihenfolge ",D36," nicht richtig! Beide Einzel tauschen."),IF(W43>W45,CONCATENATE("Achtung! Teamreihenfolge ",D38," nicht richtig! 1. und 2. Doppel tauschen."),IF(W45>W47,CONCATENATE("Achtung! Teamreihenfolge ",D38," nicht richtig! 2. und 3. Doppel tauschen."),IF(AND(W49>=W50,W50>0),CONCATENATE("Achtung! Teamreihenfolge ",D38," nicht richtig! Beide Einzel tauschen."),""))))))
A33: Spielberichtsbogen
A34: Match Report Sheet
A36: Heimteam: | L36: Gruppe: | M36: =Gruppe -> II
C37: Home team | L37: Group
A38: Gastteam: | J38: Austragungsort: | M38: =Austragungsort -> Sporthalle Berlin | Y38: Heimteam | AA38: Gastteam | AD38: Text für meinspielplan.de
C39: Guest team | L39: Venue | Y39: 1 | Z39: =VLOOKUP(CONCATENATE($D36," ",Y39),Setzlisten!$A:$E,5,0) -> #N/A | AA39: =VLOOKUP(CONCATENATE($D38," ",Y39),Setzlisten!$A:$E,5,0) -> #N/A | AB39: 1 | AD39: =CONCATENATE(A43,": ",D43," mit ",D44," - ",G43," mit ",G44,", ",I43,":",J43,", ",K43,":",L43,IF(M43="","",CONCATENATE(", ",M43,":",N43)),CHAR(10),A45,": ",D45," mit ",D46," - ",G45," mit ",G46,", ",I45,":",J45,", ",K45,":",L45,IF(M45="","",CONCATENATE(", ",M45,":",N45)),CHAR(10),A47,": ",D47," mit ",D48," - ",G47," mit ",G48,", ",I47,":",J47,", ",K47,":",L47,IF(M47="","",CONCATENATE(", ",M47,":",N47)),CHAR(10),A49,": ",D49," - ",G49,", ",I49,":",J49,", ",K49,":",L49,IF(M49="","",CONCATENATE(", ",M49,":",N49)),CHAR(10),A50,": ",D50," - ",G50,", ",I50,":",J50,", ",K50,":",L50,IF(M50="","",CONCATENATE(", ",M50,":",N50))) -> 1. Doppel 1st Doubles: mit - mit , :, : 2. Doppel 2nd Doubles: mit - mit , :, : 3. Doppel 3rd Doubles: mit - mit , :, : 1. Einzel 1st Singles: - , :, : 2. Einzel 2nd Singles: - , :, :
A40: Beginn: (Start) | C40: RL-Pos. | D40: Heimteam Home team | F40: RL-Pos. | G40: Gastteam Guest team | I40: 1. Satz 1st Game | K40: 2. Satz 2nd Game | M40: 3. Satz 3rd Game | O40: Punkte (Points) | Q40: Sätze (Games) | S40: Spiele (Matches) | V40: RL-Pos. Heim-team | W40: RL-Pos. Gast-team | Y40: 2 | Z40: =VLOOKUP(CONCATENATE($D36," ",Y40),Setzlisten!$A:$E,5,0) -> #N/A | AA40: =VLOOKUP(CONCATENATE($D38," ",Y40),Setzlisten!$A:$E,5,0) -> #N/A | AB40: 2
A41: =A10 -> 0.375 | O41: Heim Home | P41: Gast Guest | Q41: Heim Home | R41: Gast Guest | S41: Heim Home | T41: Gast Guest | Y41: 3 | Z41: =VLOOKUP(CONCATENATE($D36," ",Y41),Setzlisten!$A:$E,5,0) -> #N/A | AA41: =VLOOKUP(CONCATENATE($D38," ",Y41),Setzlisten!$A:$E,5,0) -> #N/A | AB41: 3
Y42: 4 | Z42: =VLOOKUP(CONCATENATE($D36," ",Y42),Setzlisten!$A:$E,5,0) -> #N/A | AA42: =VLOOKUP(CONCATENATE($D38," ",Y42),Setzlisten!$A:$E,5,0) -> #N/A | AB42: 4
A43: 1. Doppel 1st Doubles | C43: =IF(D43="",0,VLOOKUP(D43,$Z39:$AB53,3,0)) -> 0 | F43: =IF(G43="",0,VLOOKUP(G43,$AA39:$AB53,2,0)) -> 0 | O43: =IF(I43="","",SUM(I43,K43,M43)) | P43: =IF(J43="","",SUM(J43,L43,N43)) | Q43: =IF(I43="","",IF(I43>J43,1,0)+IF(K43>L43,1,0)+IF(M43="",0,IF(M43>N43,1,0))) | R43: =IF(I43="","",IF(J43>I43,1,0)+IF(L43>K43,1,0)+IF(M43="",0,IF(N43>M43,1,0))) | S43: =IF(I43="","",IF(Q43>R43,1,0)) | T43: =IF(I43="","",IF(R43>Q43,1,0)) | V43: =C43+C44 -> 0 | W43: =F43+F44 -> 0 | Y43: 5 | Z43: =VLOOKUP(CONCATENATE($D36," ",Y43),Setzlisten!$A:$E,5,0) -> #N/A | AA43: =VLOOKUP(CONCATENATE($D38," ",Y43),Setzlisten!$A:$E,5,0) -> #N/A | AB43: 5
C44: =IF(D44="",0,VLOOKUP(D44,$Z39:$AB53,3,0)) -> 0 | F44: =IF(G44="",0,VLOOKUP(G44,$AA39:$AB53,2,0)) -> 0 | Y44: 6 | Z44: =VLOOKUP(CONCATENATE($D36," ",Y44),Setzlisten!$A:$E,5,0) -> #N/A | AA44: =VLOOKUP(CONCATENATE($D38," ",Y44),Setzlisten!$A:$E,5,0) -> #N/A | AB44: 6
A45: 2. Doppel 2nd Doubles | C45: =IF(D45="",0,VLOOKUP(D45,$Z39:$AB53,3,0)) -> 0 | F45: =IF(G45="",0,VLOOKUP(G45,$AA39:$AB53,2,0)) -> 0 | O45: =IF(I45="","",SUM(I45,K45,M45)) | P45: =IF(J45="","",SUM(J45,L45,N45)) | Q45: =IF(I45="","",IF(I45>J45,1,0)+IF(K45>L45,1,0)+IF(M45="",0,IF(M45>N45,1,0))) | R45: =IF(I45="","",IF(J45>I45,1,0)+IF(L45>K45,1,0)+IF(M45="",0,IF(N45>M45,1,0))) | S45: =IF(I45="","",IF(Q45>R45,1,0)) | T45: =IF(I45="","",IF(R45>Q45,1,0)) | V45: =C45+C46 -> 0 | W45: =F45+F46 -> 0 | Y45: 7 | Z45: =VLOOKUP(CONCATENATE($D36," ",Y45),Setzlisten!$A:$E,5,0) -> #N/A | AA45: =VLOOKUP(CONCATENATE($D38," ",Y45),Setzlisten!$A:$E,5,0) -> #N/A | AB45: 7 | AD45: ↑ Zelle kopieren ↓ nur "Werte" unten einfügen
...

Sheet 2.Begegnung
A1: Queere Badminton Liga | F1: =IF(V12>V14,CONCATENATE("Achtung! Teamreihenfolge ",D5," nicht richtig! 1. und 2. Doppel tauschen."),IF(V14>V16,CONCATENATE("Achtung! Teamreihenfolge ",D5," nicht richtig! 2. und 3. Doppel tauschen."),IF(AND(V18>=V19,V19>0),CONCATENATE("Achtung! Teamreihenfolge ",D5," nicht richtig! Beide Einzel tauschen."),IF(W12>W14,CONCATENATE("Achtung! Teamreihenfolge ",D7," nicht richtig! 1. und 2. Doppel tauschen."),IF(W14>W16,CONCATENATE("Achtung! Teamreihenfolge ",D7," nicht richtig! 2. und 3. Doppel tauschen."),IF(AND(W18>=W19,W19>0),CONCATENATE("Achtung! Teamreihenfolge ",D7," nicht richtig! Beide Einzel tauschen."),""))))))
A2: Spielberichtsbogen
A3: Match Report Sheet
A5: Heimteam: | L5: Gruppe: | M5: =Gruppe -> II
C6: Home team | L6: Group
A7: Gastteam: | J7: Austragungsort: | M7: =Austragungsort -> Sporthalle Berlin | Y7: Heimteam | AA7: Gastteam | AD7: Text für meinspielplan.de
C8: Guest team | L8: Venue | Y8: 1 | Z8: =VLOOKUP(CONCATENATE($D5," ",Y8),Setzlisten!$A:$E,5,0) -> #N/A | AA8: =VLOOKUP(CONCATENATE($D7," ",Y8),Setzlisten!$A:$E,5,0) -> #N/A | AB8: 1 | AD8: =CONCATENATE(A12,": ",D12," mit ",D13," - ",G12," mit ",G13,", ",I12,":",J12,", ",K12,":",L12,IF(M12="","",CONCATENATE(", ",M12,":",N12)),CHAR(10),A14,": ",D14," mit ",D15," - ",G14," mit ",G15,", ",I14,":",J14,", ",K14,":",L14,IF(M14="","",CONCATENATE(", ",M14,":",N14)),CHAR(10),A16,": ",D16," mit ",D17," - ",G16," mit ",G17,", ",I16,":",J16,", ",K16,":",L16,IF(M16="","",CONCATENATE(", ",M16,":",N16)),CHAR(10),A18,": ",D18," - ",G18,", ",I18,":",J18,", ",K18,":",L18,IF(M18="","",CONCATENATE(", ",M18,":",N18)),CHAR(10),A19,": ",D19," - ",G19,", ",I19,":",J19,", ",K19,":",L19,IF(M19="","",CONCATENATE(", ",M19,":",N19))) -> 1. Doppel 1st Doubles: mit - mit , :, : 2. Doppel 2nd Doubles: mit - mit , :, : 3. Doppel 3rd Doubles: mit - mit , :, : 1. Einzel 1st Singles: - , :, : 2. Einzel 2nd Singles: - , :, :
A9: Beginn: (Start) | C9: RL-Pos. | D9: Heimteam Home team | F9: RL-Pos. | G9: Gastteam Guest team | I9: 1. Satz 1st Game | K9: 2. Satz 2nd Game | M9: 3. Satz 3rd Game | O9: Punkte (Points) | Q9: Sätze (Games) | S9: Spiele (Matches) | V9: RL-Pos. Heim-team | W9: RL-Pos. Gast-team | Y9: 2 | Z9: =VLOOKUP(CONCATENATE($D5," ",Y9),Setzlisten!$A:$E,5,0) -> #N/A | AA9: =VLOOKUP(CONCATENATE($D7," ",Y9),Setzlisten!$A:$E,5,0) -> #N/A | AB9: 2
A10: =Allgemeines!G3 -> 0.4375 | O10: Heim Home | P10: Gast Guest | Q10: Heim Home | R10: Gast Guest | S10: Heim Home | T10: Gast Guest | Y10: 3 | Z10: =VLOOKUP(CONCATENATE($D5," ",Y10),Setzlisten!$A:$E,5,0) -> #N/A | AA10: =VLOOKUP(CONCATENATE($D7," ",Y10),Setzlisten!$A:$E,5,0) -> #N/A | AB10: 3
Y11: 4 | Z11: =VLOOKUP(CONCATENATE($D5," ",Y11),Setzlisten!$A:$E,5,0) -> #N/A | AA11: =VLOOKUP(CONCATENATE($D7," ",Y11),Setzlisten!$A:$E,5,0) -> #N/A | AB11: 4
A12: 1. Doppel 1st Doubles | C12: =IF(D12="",0,VLOOKUP(D12,$Z8:$AB22,3,0)) -> 0 | F12: =IF(G12="",0,VLOOKUP(G12,$AA8:$AB22,2,0)) -> 0 | O12: =IF(I12="","",SUM(I12,K12,M12)) | P12: =IF(J12="","",SUM(J12,L12,N12)) | Q12: =IF(I12="","",IF(I12>J12,1,0)+IF(K12>L12,1,0)+IF(M12="",0,IF(M12>N12,1,0))) | R12: =IF(I12="","",IF(J12>I12,1,0)+IF(L12>K12,1,0)+IF(M12="",0,IF(N12>M12,1,0))) | S12: =IF(I12="","",IF(Q12>R12,1,0)) | T12: =IF(I12="","",IF(R12>Q12,1,0)) | V12: =C12+C13 -> 0 | W12: =F12+F13 -> 0 | Y12: 5 | Z12: =VLOOKUP(CONCATENATE($D5," ",Y12),Setzlisten!$A:$E,5,0) -> #N/A | AA12: =VLOOKUP(CONCATENATE($D7," ",Y12),Setzlisten!$A:$E,5,0) -> #N/A | AB12: 5
C13: =IF(D13="",0,VLOOKUP(D13,$Z8:$AB22,3,0)) -> 0 | F13: =IF(G13="",0,VLOOKUP(G13,$AA8:$AB22,2,0)) -> 0 | Y13: 6 | Z13: =VLOOKUP(CONCATENATE($D5," ",Y13),Setzlisten!$A:$E,5,0) -> #N/A | AA13: =VLOOKUP(CONCATENATE($D7," ",Y13),Setzlisten!$A:$E,5,0) -> #N/A | AB13: 6
A14: 2. Doppel 2nd Doubles | C14: =IF(D14="",0,VLOOKUP(D14,$Z8:$AB22,3,0)) -> 0 | F14: =IF(G14="",0,VLOOKUP(G14,$AA8:$AB22,2,0)) -> 0 | O14: =IF(I14="","",SUM(I14,K14,M14)) | P14: =IF(J14="","",SUM(J14,L14,N14)) | Q14: =IF(I14="","",IF(I14>J14,1,0)+IF(K14>L14,1,0)+IF(M14="",0,IF(M14>N14,1,0))) | R14: =IF(I14="","",IF(J14>I14,1,0)+IF(L14>K14,1,0)+IF(M14="",0,IF(N14>M14,1,0))) | S14: =IF(I14="","",IF(Q14>R14,1,0)) | T14: =IF(I14="","",IF(R14>Q14,1,0)) | V14: =C14+C15 -> 0 | W14: =F14+F15 -> 0 | Y14: 7 | Z14: =VLOOKUP(CONCATENATE($D5," ",Y14),Setzlisten!$A:$E,5,0) -> #N/A | AA14: =VLOOKUP(CONCATENATE($D7," ",Y14),Setzlisten!$A:$E,5,0) -> #N/A | AB14: 7 | AD14: ↑ Zelle kopieren ↓ nur "Werte" unten einfügen
C15: =IF(D15="",0,VLOOKUP(D15,$Z8:$AB22,3,0)) -> 0 | F15: =IF(G15="",0,VLOOKUP(G15,$AA8:$AB22,2,0)) -> 0 | Y15: 8 | Z15: =VLOOKUP(CONCATENATE($D5," ",Y15),Setzlisten!$A:$E,5,0) -> #N/A | AA15: =VLOOKUP(CONCATENATE($D7," ",Y15),Setzlisten!$A:$E,5,0) -> #N/A | AB15: 8
A16: 3. Doppel 3rd Doubles | C16: =IF(D16="",0,VLOOKUP(D16,$Z8:$AB22,3,0)) -> 0 | F16: =IF(G16="",0,VLOOKUP(G16,$AA8:$AB22,2,0)) -> 0 | O16: =IF(I16="","",SUM(I16,K16,M16)) | P16: =IF(J16="","",SUM(J16,L16,N16)) | Q16: =IF(I16="","",IF(I16>J16,1,0)+IF(K16>L16,1,0)+IF(M16="",0,IF(M16>N16,1,0))) | R16: =IF(I16="","",IF(J16>I16,1,0)+IF(L16>K16,1,0)+IF(M16="",0,IF(N16>M16,1,0))) | S16: =IF(I16="","",IF(Q16>R16,1,0)) | T16: =IF(I16="","",IF(R16>Q16,1,0)) | V16: =C16+C17 -> 0 | W16: =F16+F17 -> 0 | Y16: 9 | Z16: =VLOOKUP(CONCATENATE($D5," ",Y16),Setzlisten!$A:$E,5,0) -> #N/A | AA16: =VLOOKUP(CONCATENATE($D7," ",Y16),Setzlisten!$A:$E,5,0) -> #N/A | AB16: 9
C17: =IF(D17="",0,VLOOKUP(D17,$Z8:$AB22,3,0)) -> 0 | F17: =IF(G17="",0,VLOOKUP(G17,$AA8:$AB22,2,0)) -> 0 | Y17: 10 | Z17: =VLOOKUP(CONCATENATE($D5," ",Y17),Setzlisten!$A:$E,5,0) -> #N/A | AA17: =VLOOKUP(CONCATENATE($D7," ",Y17),Setzlisten!$A:$E,5,0) -> #N/A | AB17: 10
A18: 1. Einzel 1st Singles | C18: =IF(D18="",0,VLOOKUP(D18,$Z8:$AB22,3,0)) -> 0 | F18: =IF(G18="",0,VLOOKUP(G18,$AA8:$AB22,2,0)) -> 0 | O18: =IF(I18="","",SUM(I18,K18,M18)) | P18: =IF(J18="","",SUM(J18,L18,N18)) | Q18: =IF(I18="","",IF(I18>J18,1,0)+IF(K18>L18,1,0)+IF(M18="",0,IF(M18>N18,1,0))) | R18: =IF(I18="","",IF(J18>I18,1,0)+IF(L18>K18,1,0)+IF(M18="",0,IF(N18>M18,1,0))) | S18: =IF(I18="","",IF(Q18>R18,1,0)) | T18: =IF(I18="","",IF(R18>Q18,1,0)) | V18: =C18 -> 0 | W18: =F18 -> 0 | Y18: 11 | Z18: =VLOOKUP(CONCATENATE($D5," ",Y18),Setzlisten!$A:$E,5,0) -> #N/A | AA18: =VLOOKUP(CONCATENATE($D7," ",Y18),Setzlisten!$A:$E,5,0) -> #N/A | AB18: 11
A19: 2. Einzel 2nd Singles | C19: =IF(D19="",0,VLOOKUP(D19,$Z8:$AB22,3,0)) -> 0 | F19: =IF(G19="",0,VLOOKUP(G19,$AA8:$AB22,2,0)) -> 0 | O19: =IF(I19="","",SUM(I19,K19,M19)) | P19: =IF(J19="","",SUM(J19,L19,N19)) | Q19: =IF(I19="","",IF(I19>J19,1,0)+IF(K19>L19,1,0)+IF(M19="",0,IF(M19>N19,1,0))) | R19: =IF(I19="","",IF(J19>I19,1,0)+IF(L19>K19,1,0)+IF(M19="",0,IF(N19>M19,1,0))) | S19: =IF(I19="","",IF(Q19>R19,1,0)) | T19: =IF(I19="","",IF(R19>Q19,1,0)) | V19: =C19 -> 0 | W19: =F19 -> 0 | Y19: 12 | Z19: =VLOOKUP(CONCATENATE($D5," ",Y19),Setzlisten!$A:$E,5,0) -> #N/A | AA19: =VLOOKUP(CONCATENATE($D7," ",Y19),Setzlisten!$A:$E,5,0) -> #N/A | AB19: 12
Y20: 13 | Z20: =VLOOKUP(CONCATENATE($D5," ",Y20),Setzlisten!$A:$E,5,0) -> #N/A | AA20: =VLOOKUP(CONCATENATE($D7," ",Y20),Setzlisten!$A:$E,5,0) -> #N/A | AB20: 13
A21: Ende (End): | C21: Sieger: Winner | E21: =IF(S21="","",IF(S21>T21,D5,D7)) | I21: Ergebnis: Result | O21: =IF(O12="","",SUM(O12:O19)) | P21: =IF(P12="","",SUM(P12:P19)) | Q21: =IF(Q12="","",SUM(Q12:Q19)) | R21: =IF(R12="","",SUM(R12:R19)) | S21: =IF(S12="","",SUM(S12:S19)) | T21: =IF(T12="","",SUM(T12:T19)) | Y21: 14 | Z21: =VLOOKUP(CONCATENATE($D5," ",Y21),Setzlisten!$A:$E,5,0) -> #N/A | AA21: =VLOOKUP(CONCATENATE($D7," ",Y21),Setzlisten!$A:$E,5,0) -> #N/A | AB21: 14
A22: =Allgemeines!H3 -> 0.5 | Y22: 15 | Z22: =VLOOKUP(CONCATENATE($D5," ",Y22),Setzlisten!$A:$E,5,0) -> #N/A | AA22: =VLOOKUP(CONCATENATE($D7," ",Y22),Setzlisten!$A:$E,5,0) -> #N/A | AB22: 15
D24: Besondere Vorkommnisse: Noteworthy Events
A26: Die Richtigkeit der Angaben wird bescheinigt. Das Spiel hat unter Beachtung der Spielordnung stattgefunden. The accuracy of the information is certified. The match took place in accordance with the League and Match Rules.
A27: =Allgemeines!$B$3 -> Hamburg | E27: =Allgemeines!$B$4 -> 46023
A29: Ort (Place) | E29: Datum (Date) | G29: Gruppenkoordinator:in | J29: Kapitän:in Heimverein | P29: Kapitän:in Gastverein
G30: Group Coordinator | J30: Captain Home Club | P30: Captain Guest Club
G31: =Allgemeines!$D$2 -> George Washington | J31: =IF(D5="","",VLOOKUP(D5,Allgemeines!$B$7:$D$12,3,0)) | P31: =IF(D7="","",VLOOKUP(D7,Allgemeines!$B$7:$D$12,3,0))
A32: Queere Badminton Liga | F32: =IF(V43>V45,CONCATENATE("Achtung! Teamreihenfolge ",D36," nicht richtig! 1. und 2. Doppel tauschen."),IF(V45>V47,CONCATENATE("Achtung! Teamreihenfolge ",D36," nicht richtig! 2. und 3. Doppel tauschen."),IF(AND(V49>=V50,V50>0),CONCATENATE("Achtung! Teamreihenfolge ",D36," nicht richtig! Beide Einzel tauschen."),IF(W43>W45,CONCATENATE("Achtung! Teamreihenfolge ",D38," nicht richtig! 1. und 2. Doppel tauschen."),IF(W45>W47,CONCATENATE("Achtung! Teamreihenfolge ",D38," nicht richtig! 2. und 3. Doppel tauschen."),IF(AND(W49>=W50,W50>0),CONCATENATE("Achtung! Teamreihenfolge ",D38," nicht richtig! Beide Einzel tauschen."),""))))))
A33: Spielberichtsbogen
A34: Match Report Sheet
A36: Heimteam: | L36: Gruppe: | M36: =Gruppe -> II
C37: Home team | L37: Group
A38: Gastteam: | J38: Austragungsort: | M38: =Austragungsort -> Sporthalle Berlin | Y38: Heimteam | AA38: Gastteam | AD38: Text für meinspielplan.de
C39: Guest team | L39: Venue | Y39: 1 | Z39: =VLOOKUP(CONCATENATE($D36," ",Y39),Setzlisten!$A:$E,5,0) -> #N/A | AA39: =VLOOKUP(CONCATENATE($D38," ",Y39),Setzlisten!$A:$E,5,0) -> #N/A | AB39: 1 | AD39: =CONCATENATE(A43,": ",D43," mit ",D44," - ",G43," mit ",G44,", ",I43,":",J43,", ",K43,":",L43,IF(M43="","",CONCATENATE(", ",M43,":",N43)),CHAR(10),A45,": ",D45," mit ",D46," - ",G45," mit ",G46,", ",I45,":",J45,", ",K45,":",L45,IF(M45="","",CONCATENATE(", ",M45,":",N45)),CHAR(10),A47,": ",D47," mit ",D48," - ",G47," mit ",G48,", ",I47,":",J47,", ",K47,":",L47,IF(M47="","",CONCATENATE(", ",M47,":",N47)),CHAR(10),A49,": ",D49," - ",G49,", ",I49,":",J49,", ",K49,":",L49,IF(M49="","",CONCATENATE(", ",M49,":",N49)),CHAR(10),A50,": ",D50," - ",G50,", ",I50,":",J50,", ",K50,":",L50,IF(M50="","",CONCATENATE(", ",M50,":",N50))) -> 1. Doppel 1st Doubles: mit - mit , :, : 2. Doppel 2nd Doubles: mit - mit , :, : 3. Doppel 3rd Doubles: mit - mit , :, : 1. Einzel 1st Singles: - , :, : 2. Einzel 2nd Singles: - , :, :
A40: Beginn: (Start) | C40: RL-Pos. | D40: Heimteam Home team | F40: RL-Pos. | G40: Gastteam Guest team | I40: 1. Satz 1st Game | K40: 2. Satz 2nd Game | M40: 3. Satz 3rd Game | O40: Punkte (Points) | Q40: Sätze (Games) | S40: Spiele (Matches) | V40: RL-Pos. Heim-team | W40: RL-Pos. Gast-team | Y40: 2 | Z40: =VLOOKUP(CONCATENATE($D36," ",Y40),Setzlisten!$A:$E,5,0) -> #N/A | AA40: =VLOOKUP(CONCATENATE($D38," ",Y40),Setzlisten!$A:$E,5,0) -> #N/A | AB40: 2
A41: =A10 -> 0.4375 | O41: Heim Home | P41: Gast Guest | Q41: Heim Home | R41: Gast Guest | S41: Heim Home | T41: Gast Guest | Y41: 3 | Z41: =VLOOKUP(CONCATENATE($D36," ",Y41),Setzlisten!$A:$E,5,0) -> #N/A | AA41: =VLOOKUP(CONCATENATE($D38," ",Y41),Setzlisten!$A:$E,5,0) -> #N/A | AB41: 3
Y42: 4 | Z42: =VLOOKUP(CONCATENATE($D36," ",Y42),Setzlisten!$A:$E,5,0) -> #N/A | AA42: =VLOOKUP(CONCATENATE($D38," ",Y42),Setzlisten!$A:$E,5,0) -> #N/A | AB42: 4
A43: 1. Doppel 1st Doubles | C43: =IF(D43="",0,VLOOKUP(D43,$Z39:$AB53,3,0)) -> 0 | F43: =IF(G43="",0,VLOOKUP(G43,$AA39:$AB53,2,0)) -> 0 | O43: =IF(I43="","",SUM(I43,K43,M43)) | P43: =IF(J43="","",SUM(J43,L43,N43)) | Q43: =IF(I43="","",IF(I43>J43,1,0)+IF(K43>L43,1,0)+IF(M43="",0,IF(M43>N43,1,0))) | R43: =IF(I43="","",IF(J43>I43,1,0)+IF(L43>K43,1,0)+IF(M43="",0,IF(N43>M43,1,0))) | S43: =IF(I43="","",IF(Q43>R43,1,0)) | T43: =IF(I43="","",IF(R43>Q43,1,0)) | V43: =C43+C44 -> 0 | W43: =F43+F44 -> 0 | Y43: 5 | Z43: =VLOOKUP(CONCATENATE($D36," ",Y43),Setzlisten!$A:$E,5,0) -> #N/A | AA43: =VLOOKUP(CONCATENATE($D38," ",Y43),Setzlisten!$A:$E,5,0) -> #N/A | AB43: 5
C44: =IF(D44="",0,VLOOKUP(D44,$Z39:$AB53,3,0)) -> 0 | F44: =IF(G44="",0,VLOOKUP(G44,$AA39:$AB53,2,0)) -> 0 | Y44: 6 | Z44: =VLOOKUP(CONCATENATE($D36," ",Y44),Setzlisten!$A:$E,5,0) -> #N/A | AA44: =VLOOKUP(CONCATENATE($D38," ",Y44),Setzlisten!$A:$E,5,0) -> #N/A | AB44: 6
A45: 2. Doppel 2nd Doubles | C45: =IF(D45="",0,VLOOKUP(D45,$Z39:$AB53,3,0)) -> 0 | F45: =IF(G45="",0,VLOOKUP(G45,$AA39:$AB53,2,0)) -> 0 | O45: =IF(I45="","",SUM(I45,K45,M45)) | P45: =IF(J45="","",SUM(J45,L45,N45)) | Q45: =IF(I45="","",IF(I45>J45,1,0)+IF(K45>L45,1,0)+IF(M45="",0,IF(M45>N45,1,0))) | R45: =IF(I45="","",IF(J45>I45,1,0)+IF(L45>K45,1,0)+IF(M45="",0,IF(N45>M45,1,0))) | S45: =IF(I45="","",IF(Q45>R45,1,0)) | T45: =IF(I45="","",IF(R45>Q45,1,0)) | V45: =C45+C46 -> 0 | W45: =F45+F46 -> 0 | Y45: 7 | Z45: =VLOOKUP(CONCATENATE($D36," ",Y45),Setzlisten!$A:$E,5,0) -> #N/A | AA45: =VLOOKUP(CONCATENATE($D38," ",Y45),Setzlisten!$A:$E,5,0) -> #N/A | AB45: 7 | AD45: ↑ Zelle kopieren ↓ nur "Werte" unten einfügen
...

Sheet 3.Begegnung
A1: Queere Badminton Liga | F1: =IF(V12>V14,CONCATENATE("Achtung! Teamreihenfolge ",D5," nicht richtig! 1. und 2. Doppel tauschen."),IF(V14>V16,CONCATENATE("Achtung! Teamreihenfolge ",D5," nicht richtig! 2. und 3. Doppel tauschen."),IF(AND(V18>=V19,V19>0),CONCATENATE("Achtung! Teamreihenfolge ",D5," nicht richtig! Beide Einzel tauschen."),IF(W12>W14,CONCATENATE("Achtung! Teamreihenfolge ",D7," nicht richtig! 1. und 2. Doppel tauschen."),IF(W14>W16,CONCATENATE("Achtung! Teamreihenfolge ",D7," nicht richtig! 2. und 3. Doppel tauschen."),IF(AND(W18>=W19,W19>0),CONCATENATE("Achtung! Teamreihenfolge ",D7," nicht richtig! Beide Einzel tauschen."),""))))))
A2: Spielberichtsbogen
A3: Match Report Sheet
A5: Heimteam: | L5: Gruppe: | M5: =Gruppe -> II
C6: Home team | L6: Group
A7: Gastteam: | J7: Austragungsort: | M7: =Austragungsort -> Sporthalle Berlin | Y7: Heimteam | AA7: Gastteam | AD7: Text für meinspielplan.de
C8: Guest team | L8: Venue | Y8: 1 | Z8: =VLOOKUP(CONCATENATE($D5," ",Y8),Setzlisten!$A:$E,5,0) -> #N/A | AA8: =VLOOKUP(CONCATENATE($D7," ",Y8),Setzlisten!$A:$E,5,0) -> #N/A | AB8: 1 | AD8: =CONCATENATE(A12,": ",D12," mit ",D13," - ",G12," mit ",G13,", ",I12,":",J12,", ",K12,":",L12,IF(M12="","",CONCATENATE(", ",M12,":",N12)),CHAR(10),A14,": ",D14," mit ",D15," - ",G14," mit ",G15,", ",I14,":",J14,", ",K14,":",L14,IF(M14="","",CONCATENATE(", ",M14,":",N14)),CHAR(10),A16,": ",D16," mit ",D17," - ",G16," mit ",G17,", ",I16,":",J16,", ",K16,":",L16,IF(M16="","",CONCATENATE(", ",M16,":",N16)),CHAR(10),A18,": ",D18," - ",G18,", ",I18,":",J18,", ",K18,":",L18,IF(M18="","",CONCATENATE(", ",M18,":",N18)),CHAR(10),A19,": ",D19," - ",G19,", ",I19,":",J19,", ",K19,":",L19,IF(M19="","",CONCATENATE(", ",M19,":",N19))) -> 1. Doppel 1st Doubles: mit - mit , :, : 2. Doppel 2nd Doubles: mit - mit , :, : 3. Doppel 3rd Doubles: mit - mit , :, : 1. Einzel 1st Singles: - , :, : 2. Einzel 2nd Singles: - , :, :
A9: Beginn: (Start) | C9: RL-Pos. | D9: Heimteam Home team | F9: RL-Pos. | G9: Gastteam Guest team | I9: 1. Satz 1st Game | K9: 2. Satz 2nd Game | M9: 3. Satz 3rd Game | O9: Punkte (Points) | Q9: Sätze (Games) | S9: Spiele (Matches) | V9: RL-Pos. Heim-team | W9: RL-Pos. Gast-team | Y9: 2 | Z9: =VLOOKUP(CONCATENATE($D5," ",Y9),Setzlisten!$A:$E,5,0) -> #N/A | AA9: =VLOOKUP(CONCATENATE($D7," ",Y9),Setzlisten!$A:$E,5,0) -> #N/A | AB9: 2
A10: =Allgemeines!G4 -> 0.52083333 | O10: Heim Home | P10: Gast Guest | Q10: Heim Home | R10: Gast Guest | S10: Heim Home | T10: Gast Guest | Y10: 3 | Z10: =VLOOKUP(CONCATENATE($D5," ",Y10),Setzlisten!$A:$E,5,0) -> #N/A | AA10: =VLOOKUP(CONCATENATE($D7," ",Y10),Setzlisten!$A:$E,5,0) -> #N/A | AB10: 3
Y11: 4 | Z11: =VLOOKUP(CONCATENATE($D5," ",Y11),Setzlisten!$A:$E,5,0) -> #N/A | AA11: =VLOOKUP(CONCATENATE($D7," ",Y11),Setzlisten!$A:$E,5,0) -> #N/A | AB11: 4
A12: 1. Doppel 1st Doubles | C12: =IF(D12="",0,VLOOKUP(D12,$Z8:$AB22,3,0)) -> 0 | F12: =IF(G12="",0,VLOOKUP(G12,$AA8:$AB22,2,0)) -> 0 | O12: =IF(I12="","",SUM(I12,K12,M12)) | P12: =IF(J12="","",SUM(J12,L12,N12)) | Q12: =IF(I12="","",IF(I12>J12,1,0)+IF(K12>L12,1,0)+IF(M12="",0,IF(M12>N12,1,0))) | R12: =IF(I12="","",IF(J12>I12,1,0)+IF(L12>K12,1,0)+IF(M12="",0,IF(N12>M12,1,0))) | S12: =IF(I12="","",IF(Q12>R12,1,0)) | T12: =IF(I12="","",IF(R12>Q12,1,0)) | V12: =C12+C13 -> 0 | W12: =F12+F13 -> 0 | Y12: 5 | Z12: =VLOOKUP(CONCATENATE($D5," ",Y12),Setzlisten!$A:$E,5,0) -> #N/A | AA12: =VLOOKUP(CONCATENATE($D7," ",Y12),Setzlisten!$A:$E,5,0) -> #N/A | AB12: 5
C13: =IF(D13="",0,VLOOKUP(D13,$Z8:$AB22,3,0)) -> 0 | F13: =IF(G13="",0,VLOOKUP(G13,$AA8:$AB22,2,0)) -> 0 | Y13: 6 | Z13: =VLOOKUP(CONCATENATE($D5," ",Y13),Setzlisten!$A:$E,5,0) -> #N/A | AA13: =VLOOKUP(CONCATENATE($D7," ",Y13),Setzlisten!$A:$E,5,0) -> #N/A | AB13: 6
A14: 2. Doppel 2nd Doubles | C14: =IF(D14="",0,VLOOKUP(D14,$Z8:$AB22,3,0)) -> 0 | F14: =IF(G14="",0,VLOOKUP(G14,$AA8:$AB22,2,0)) -> 0 | O14: =IF(I14="","",SUM(I14,K14,M14)) | P14: =IF(J14="","",SUM(J14,L14,N14)) | Q14: =IF(I14="","",IF(I14>J14,1,0)+IF(K14>L14,1,0)+IF(M14="",0,IF(M14>N14,1,0))) | R14: =IF(I14="","",IF(J14>I14,1,0)+IF(L14>K14,1,0)+IF(M14="",0,IF(N14>M14,1,0))) | S14: =IF(I14="","",IF(Q14>R14,1,0)) | T14: =IF(I14="","",IF(R14>Q14,1,0)) | V14: =C14+C15 -> 0 | W14: =F14+F15 -> 0 | Y14: 7 | Z14: =VLOOKUP(CONCATENATE($D5," ",Y14),Setzlisten!$A:$E,5,0) -> #N/A | AA14: =VLOOKUP(CONCATENATE($D7," ",Y14),Setzlisten!$A:$E,5,0) -> #N/A | AB14: 7 | AD14: ↑ Zelle kopieren ↓ nur "Werte" unten einfügen
C15: =IF(D15="",0,VLOOKUP(D15,$Z8:$AB22,3,0)) -> 0 | F15: =IF(G15="",0,VLOOKUP(G15,$AA8:$AB22,2,0)) -> 0 | Y15: 8 | Z15: =VLOOKUP(CONCATENATE($D5," ",Y15),Setzlisten!$A:$E,5,0) -> #N/A | AA15: =VLOOKUP(CONCATENATE($D7," ",Y15),Setzlisten!$A:$E,5,0) -> #N/A | AB15: 8
A16: 3. Doppel 3rd Doubles | C16: =IF(D16="",0,VLOOKUP(D16,$Z8:$AB22,3,0)) -> 0 | F16: =IF(G16="",0,VLOOKUP(G16,$AA8:$AB22,2,0)) -> 0 | O16: =IF(I16="","",SUM(I16,K16,M16)) | P16: =IF(J16="","",SUM(J16,L16,N16)) | Q16: =IF(I16="","",IF(I16>J16,1,0)+IF(K16>L16,1,0)+IF(M16="",0,IF(M16>N16,1,0))) | R16: =IF(I16="","",IF(J16>I16,1,0)+IF(L16>K16,1,0)+IF(M16="",0,IF(N16>M16,1,0))) | S16: =IF(I16="","",IF(Q16>R16,1,0)) | T16: =IF(I16="","",IF(R16>Q16,1,0)) | V16: =C16+C17 -> 0 | W16: =F16+F17 -> 0 | Y16: 9 | Z16: =VLOOKUP(CONCATENATE($D5," ",Y16),Setzlisten!$A:$E,5,0) -> #N/A | AA16: =VLOOKUP(CONCATENATE($D7," ",Y16),Setzlisten!$A:$E,5,0) -> #N/A | AB16: 9
C17: =IF(D17="",0,VLOOKUP(D17,$Z8:$AB22,3,0)) -> 0 | F17: =IF(G17="",0,VLOOKUP(G17,$AA8:$AB22,2,0)) -> 0 | Y17: 10 | Z17: =VLOOKUP(CONCATENATE($D5," ",Y17),Setzlisten!$A:$E,5,0) -> #N/A | AA17: =VLOOKUP(CONCATENATE($D7," ",Y17),Setzlisten!$A:$E,5,0) -> #N/A | AB17: 10
A18: 1. Einzel 1st Singles | C18: =IF(D18="",0,VLOOKUP(D18,$Z8:$AB22,3,0)) -> 0 | F18: =IF(G18="",0,VLOOKUP(G18,$AA8:$AB22,2,0)) -> 0 | O18: =IF(I18="","",SUM(I18,K18,M18)) | P18: =IF(J18="","",SUM(J18,L18,N18)) | Q18: =IF(I18="","",IF(I18>J18,1,0)+IF(K18>L18,1,0)+IF(M18="",0,IF(M18>N18,1,0))) | R18: =IF(I18="","",IF(J18>I18,1,0)+IF(L18>K18,1,0)+IF(M18="",0,IF(N18>M18,1,0))) | S18: =IF(I18="","",IF(Q18>R18,1,0)) | T18: =IF(I18="","",IF(R18>Q18,1,0)) | V18: =C18 -> 0 | W18: =F18 -> 0 | Y18: 11 | Z18: =VLOOKUP(CONCATENATE($D5," ",Y18),Setzlisten!$A:$E,5,0) -> #N/A | AA18: =VLOOKUP(CONCATENATE($D7," ",Y18),Setzlisten!$A:$E,5,0) -> #N/A | AB18: 11
A19: 2. Einzel 2nd Singles | C19: =IF(D19="",0,VLOOKUP(D19,$Z8:$AB22,3,0)) -> 0 | F19: =IF(G19="",0,VLOOKUP(G19,$AA8:$AB22,2,0)) -> 0 | O19: =IF(I19="","",SUM(I19,K19,M19)) | P19: =IF(J19="","",SUM(J19,L19,N19)) | Q19: =IF(I19="","",IF(I19>J19,1,0)+IF(K19>L19,1,0)+IF(M19="",0,IF(M19>N19,1,0))) | R19: =IF(I19="","",IF(J19>I19,1,0)+IF(L19>K19,1,0)+IF(M19="",0,IF(N19>M19,1,0))) | S19: =IF(I19="","",IF(Q19>R19,1,0)) | T19: =IF(I19="","",IF(R19>Q19,1,0)) | V19: =C19 -> 0 | W19: =F19 -> 0 | Y19: 12 | Z19: =VLOOKUP(CONCATENATE($D5," ",Y19),Setzlisten!$A:$E,5,0) -> #N/A | AA19: =VLOOKUP(CONCATENATE($D7," ",Y19),Setzlisten!$A:$E,5,0) -> #N/A | AB19: 12
Y20: 13 | Z20: =VLOOKUP(CONCATENATE($D5," ",Y20),Setzlisten!$A:$E,5,0) -> #N/A | AA20: =VLOOKUP(CONCATENATE($D7," ",Y20),Setzlisten!$A:$E,5,0) -> #N/A | AB20: 13
A21: Ende (End): | C21: Sieger: Winner | E21: =IF(S21="","",IF(S21>T21,D5,D7)) | I21: Ergebnis: Result | O21: =IF(O12="","",SUM(O12:O19)) | P21: =IF(P12="","",SUM(P12:P19)) | Q21: =IF(Q12="","",SUM(Q12:Q19)) | R21: =IF(R12="","",SUM(R12:R19)) | S21: =IF(S12="","",SUM(S12:S19)) | T21: =IF(T12="","",SUM(T12:T19)) | Y21: 14 | Z21: =VLOOKUP(CONCATENATE($D5," ",Y21),Setzlisten!$A:$E,5,0) -> #N/A | AA21: =VLOOKUP(CONCATENATE($D7," ",Y21),Setzlisten!$A:$E,5,0) -> #N/A | AB21: 14
A22: =Allgemeines!H4 -> 0.58333333 | Y22: 15 | Z22: =VLOOKUP(CONCATENATE($D5," ",Y22),Setzlisten!$A:$E,5,0) -> #N/A | AA22: =VLOOKUP(CONCATENATE($D7," ",Y22),Setzlisten!$A:$E,5,0) -> #N/A | AB22: 15
D24: Besondere Vorkommnisse: Noteworthy Events
A26: Die Richtigkeit der Angaben wird bescheinigt. Das Spiel hat unter Beachtung der Spielordnung stattgefunden. The accuracy of the information is certified. The match took place in accordance with the League and Match Rules.
A27: =Allgemeines!$B$3 -> Hamburg | E27: =Allgemeines!$B$4 -> 46023
A29: Ort (Place) | E29: Datum (Date) | G29: Gruppenkoordinator:in | J29: Kapitän:in Heimverein | P29: Kapitän:in Gastverein
G30: Group Coordinator | J30: Captain Home Club | P30: Captain Guest Club
G31: =Allgemeines!$D$2 -> George Washington | J31: =IF(D5="","",VLOOKUP(D5,Allgemeines!$B$7:$D$12,3,0)) | P31: =IF(D7="","",VLOOKUP(D7,Allgemeines!$B$7:$D$12,3,0))
A32: Queere Badminton Liga | F32: =IF(V43>V45,CONCATENATE("Achtung! Teamreihenfolge ",D36," nicht richtig! 1. und 2. Doppel tauschen."),IF(V45>V47,CONCATENATE("Achtung! Teamreihenfolge ",D36," nicht richtig! 2. und 3. Doppel tauschen."),IF(AND(V49>=V50,V50>0),CONCATENATE("Achtung! Teamreihenfolge ",D36," nicht richtig! Beide Einzel tauschen."),IF(W43>W45,CONCATENATE("Achtung! Teamreihenfolge ",D38," nicht richtig! 1. und 2. Doppel tauschen."),IF(W45>W47,CONCATENATE("Achtung! Teamreihenfolge ",D38," nicht richtig! 2. und 3. Doppel tauschen."),IF(AND(W49>=W50,W50>0),CONCATENATE("Achtung! Teamreihenfolge ",D38," nicht richtig! Beide Einzel tauschen."),""))))))
A33: Spielberichtsbogen
A34: Match Report Sheet
A36: Heimteam: | L36: Gruppe: | M36: =Gruppe -> II
C37: Home team | L37: Group
A38: Gastteam: | J38: Austragungsort: | M38: =Austragungsort -> Sporthalle Berlin | Y38: Heimteam | AA38: Gastteam | AD38: Text für meinspielplan.de
C39: Guest team | L39: Venue | Y39: 1 | Z39: =VLOOKUP(CONCATENATE($D36," ",Y39),Setzlisten!$A:$E,5,0) -> #N/A | AA39: =VLOOKUP(CONCATENATE($D38," ",Y39),Setzlisten!$A:$E,5,0) -> #N/A | AB39: 1 | AD39: =CONCATENATE(A43,": ",D43," mit ",D44," - ",G43," mit ",G44,", ",I43,":",J43,", ",K43,":",L43,IF(M43="","",CONCATENATE(", ",M43,":",N43)),CHAR(10),A45,": ",D45," mit ",D46," - ",G45," mit ",G46,", ",I45,":",J45,", ",K45,":",L45,IF(M45="","",CONCATENATE(", ",M45,":",N45)),CHAR(10),A47,": ",D47," mit ",D48," - ",G47," mit ",G48,", ",I47,":",J47,", ",K47,":",L47,IF(M47="","",CONCATENATE(", ",M47,":",N47)),CHAR(10),A49,": ",D49," - ",G49,", ",I49,":",J49,", ",K49,":",L49,IF(M49="","",CONCATENATE(", ",M49,":",N49)),CHAR(10),A50,": ",D50," - ",G50,", ",I50,":",J50,", ",K50,":",L50,IF(M50="","",CONCATENATE(", ",M50,":",N50))) -> 1. Doppel 1st Doubles: mit - mit , :, : 2. Doppel 2nd Doubles: mit - mit , :, : 3. Doppel 3rd Doubles: mit - mit , :, : 1. Einzel 1st Singles: - , :, : 2. Einzel 2nd Singles: - , :, :
A40: Beginn: (Start) | C40: RL-Pos. | D40: Heimteam Home team | F40: RL-Pos. | G40: Gastteam Guest team | I40: 1. Satz 1st Game | K40: 2. Satz 2nd Game | M40: 3. Satz 3rd Game | O40: Punkte (Points) | Q40: Sätze (Games) | S40: Spiele (Matches) | V40: RL-Pos. Heim-team | W40: RL-Pos. Gast-team | Y40: 2 | Z40: =VLOOKUP(CONCATENATE($D36," ",Y40),Setzlisten!$A:$E,5,0) -> #N/A | AA40: =VLOOKUP(CONCATENATE($D38," ",Y40),Setzlisten!$A:$E,5,0) -> #N/A | AB40: 2
A41: =A10 -> 0.52083333 | O41: Heim Home | P41: Gast Guest | Q41: Heim Home | R41: Gast Guest | S41: Heim Home | T41: Gast Guest | Y41: 3 | Z41: =VLOOKUP(CONCATENATE($D36," ",Y41),Setzlisten!$A:$E,5,0) -> #N/A | AA41: =VLOOKUP(CONCATENATE($D38," ",Y41),Setzlisten!$A:$E,5,0) -> #N/A | AB41: 3
Y42: 4 | Z42: =VLOOKUP(CONCATENATE($D36," ",Y42),Setzlisten!$A:$E,5,0) -> #N/A | AA42: =VLOOKUP(CONCATENATE($D38," ",Y42),Setzlisten!$A:$E,5,0) -> #N/A | AB42: 4
A43: 1. Doppel 1st Doubles | C43: =IF(D43="",0,VLOOKUP(D43,$Z39:$AB53,3,0)) -> 0 | F43: =IF(G43="",0,VLOOKUP(G43,$AA39:$AB53,2,0)) -> 0 | O43: =IF(I43="","",SUM(I43,K43,M43)) | P43: =IF(J43="","",SUM(J43,L43,N43)) | Q43: =IF(I43="","",IF(I43>J43,1,0)+IF(K43>L43,1,0)+IF(M43="",0,IF(M43>N43,1,0))) | R43: =IF(I43="","",IF(J43>I43,1,0)+IF(L43>K43,1,0)+IF(M43="",0,IF(N43>M43,1,0))) | S43: =IF(I43="","",IF(Q43>R43,1,0)) | T43: =IF(I43="","",IF(R43>Q43,1,0)) | V43: =C43+C44 -> 0 | W43: =F43+F44 -> 0 | Y43: 5 | Z43: =VLOOKUP(CONCATENATE($D36," ",Y43),Setzlisten!$A:$E,5,0) -> #N/A | AA43: =VLOOKUP(CONCATENATE($D38," ",Y43),Setzlisten!$A:$E,5,0) -> #N/A | AB43: 5
C44: =IF(D44="",0,VLOOKUP(D44,$Z39:$AB53,3,0)) -> 0 | F44: =IF(G44="",0,VLOOKUP(G44,$AA39:$AB53,2,0)) -> 0 | Y44: 6 | Z44: =VLOOKUP(CONCATENATE($D36," ",Y44),Setzlisten!$A:$E,5,0) -> #N/A | AA44: =VLOOKUP(CONCATENATE($D38," ",Y44),Setzlisten!$A:$E,5,0) -> #N/A | AB44: 6
A45: 2. Doppel 2nd Doubles | C45: =IF(D45="",0,VLOOKUP(D45,$Z39:$AB53,3,0)) -> 0 | F45: =IF(G45="",0,VLOOKUP(G45,$AA39:$AB53,2,0)) -> 0 | O45: =IF(I45="","",SUM(I45,K45,M45)) | P45: =IF(J45="","",SUM(J45,L45,N45)) | Q45: =IF(I45="","",IF(I45>J45,1,0)+IF(K45>L45,1,0)+IF(M45="",0,IF(M45>N45,1,0))) | R45: =IF(I45="","",IF(J45>I45,1,0)+IF(L45>K45,1,0)+IF(M45="",0,IF(N45>M45,1,0))) | S45: =IF(I45="","",IF(Q45>R45,1,0)) | T45: =IF(I45="","",IF(R45>Q45,1,0)) | V45: =C45+C46 -> 0 | W45: =F45+F46 -> 0 | Y45: 7 | Z45: =VLOOKUP(CONCATENATE($D36," ",Y45),Setzlisten!$A:$E,5,0) -> #N/A | AA45: =VLOOKUP(CONCATENATE($D38," ",Y45),Setzlisten!$A:$E,5,0) -> #N/A | AB45: 7 | AD45: ↑ Zelle kopieren ↓ nur "Werte" unten einfügen
...

Sheet 4.Begegnung
A1: Queere Badminton Liga | F1: =IF(V12>V14,CONCATENATE("Achtung! Teamreihenfolge ",D5," nicht richtig! 1. und 2. Doppel tauschen."),IF(V14>V16,CONCATENATE("Achtung! Teamreihenfolge ",D5," nicht richtig! 2. und 3. Doppel tauschen."),IF(AND(V18>=V19,V19>0),CONCATENATE("Achtung! Teamreihenfolge ",D5," nicht richtig! Beide Einzel tauschen."),IF(W12>W14,CONCATENATE("Achtung! Teamreihenfolge ",D7," nicht richtig! 1. und 2. Doppel tauschen."),IF(W14>W16,CONCATENATE("Achtung! Teamreihenfolge ",D7," nicht richtig! 2. und 3. Doppel tauschen."),IF(AND(W18>=W19,W19>0),CONCATENATE("Achtung! Teamreihenfolge ",D7," nicht richtig! Beide Einzel tauschen."),""))))))
A2: Spielberichtsbogen
A3: Match Report Sheet
A5: Heimteam: | L5: Gruppe: | M5: =Gruppe -> II
C6: Home team | L6: Group
A7: Gastteam: | J7: Austragungsort: | M7: =Austragungsort -> Sporthalle Berlin | Y7: Heimteam | AA7: Gastteam | AD7: Text für meinspielplan.de
C8: Guest team | L8: Venue | Y8: 1 | Z8: =VLOOKUP(CONCATENATE($D5," ",Y8),Setzlisten!$A:$E,5,0) -> #N/A | AA8: =VLOOKUP(CONCATENATE($D7," ",Y8),Setzlisten!$A:$E,5,0) -> #N/A | AB8: 1 | AD8: =CONCATENATE(A12,": ",D12," mit ",D13," - ",G12," mit ",G13,", ",I12,":",J12,", ",K12,":",L12,IF(M12="","",CONCATENATE(", ",M12,":",N12)),CHAR(10),A14,": ",D14," mit ",D15," - ",G14," mit ",G15,", ",I14,":",J14,", ",K14,":",L14,IF(M14="","",CONCATENATE(", ",M14,":",N14)),CHAR(10),A16,": ",D16," mit ",D17," - ",G16," mit ",G17,", ",I16,":",J16,", ",K16,":",L16,IF(M16="","",CONCATENATE(", ",M16,":",N16)),CHAR(10),A18,": ",D18," - ",G18,", ",I18,":",J18,", ",K18,":",L18,IF(M18="","",CONCATENATE(", ",M18,":",N18)),CHAR(10),A19,": ",D19," - ",G19,", ",I19,":",J19,", ",K19,":",L19,IF(M19="","",CONCATENATE(", ",M19,":",N19))) -> 1. Doppel 1st Doubles: mit - mit , :, : 2. Doppel 2nd Doubles: mit - mit , :, : 3. Doppel 3rd Doubles: mit - mit , :, : 1. Einzel 1st Singles: - , :, : 2. Einzel 2nd Singles: - , :, :
A9: Beginn: (Start) | C9: RL-Pos. | D9: Heimteam Home team | F9: RL-Pos. | G9: Gastteam Guest team | I9: 1. Satz 1st Game | K9: 2. Satz 2nd Game | M9: 3. Satz 3rd Game | O9: Punkte (Points) | Q9: Sätze (Games) | S9: Spiele (Matches) | V9: RL-Pos. Heim-team | W9: RL-Pos. Gast-team | Y9: 2 | Z9: =VLOOKUP(CONCATENATE($D5," ",Y9),Setzlisten!$A:$E,5,0) -> #N/A | AA9: =VLOOKUP(CONCATENATE($D7," ",Y9),Setzlisten!$A:$E,5,0) -> #N/A | AB9: 2
A10: =Allgemeines!G5 -> 0.58333333 | O10: Heim Home | P10: Gast Guest | Q10: Heim Home | R10: Gast Guest | S10: Heim Home | T10: Gast Guest | Y10: 3 | Z10: =VLOOKUP(CONCATENATE($D5," ",Y10),Setzlisten!$A:$E,5,0) -> #N/A | AA10: =VLOOKUP(CONCATENATE($D7," ",Y10),Setzlisten!$A:$E,5,0) -> #N/A | AB10: 3
Y11: 4 | Z11: =VLOOKUP(CONCATENATE($D5," ",Y11),Setzlisten!$A:$E,5,0) -> #N/A | AA11: =VLOOKUP(CONCATENATE($D7," ",Y11),Setzlisten!$A:$E,5,0) -> #N/A | AB11: 4
A12: 1. Doppel 1st Doubles | C12: =IF(D12="",0,VLOOKUP(D12,$Z8:$AB22,3,0)) -> 0 | F12: =IF(G12="",0,VLOOKUP(G12,$AA8:$AB22,2,0)) -> 0 | O12: =IF(I12="","",SUM(I12,K12,M12)) | P12: =IF(J12="","",SUM(J12,L12,N12)) | Q12: =IF(I12="","",IF(I12>J12,1,0)+IF(K12>L12,1,0)+IF(M12="",0,IF(M12>N12,1,0))) | R12: =IF(I12="","",IF(J12>I12,1,0)+IF(L12>K12,1,0)+IF(M12="",0,IF(N12>M12,1,0))) | S12: =IF(I12="","",IF(Q12>R12,1,0)) | T12: =IF(I12="","",IF(R12>Q12,1,0)) | V12: =C12+C13 -> 0 | W12: =F12+F13 -> 0 | Y12: 5 | Z12: =VLOOKUP(CONCATENATE($D5," ",Y12),Setzlisten!$A:$E,5,0) -> #N/A | AA12: =VLOOKUP(CONCATENATE($D7," ",Y12),Setzlisten!$A:$E,5,0) -> #N/A | AB12: 5
C13: =IF(D13="",0,VLOOKUP(D13,$Z8:$AB22,3,0)) -> 0 | F13: =IF(G13="",0,VLOOKUP(G13,$AA8:$AB22,2,0)) -> 0 | Y13: 6 | Z13: =VLOOKUP(CONCATENATE($D5," ",Y13),Setzlisten!$A:$E,5,0) -> #N/A | AA13: =VLOOKUP(CONCATENATE($D7," ",Y13),Setzlisten!$A:$E,5,0) -> #N/A | AB13: 6
A14: 2. Doppel 2nd Doubles | C14: =IF(D14="",0,VLOOKUP(D14,$Z8:$AB22,3,0)) -> 0 | F14: =IF(G14="",0,VLOOKUP(G14,$AA8:$AB22,2,0)) -> 0 | O14: =IF(I14="","",SUM(I14,K14,M14)) | P14: =IF(J14="","",SUM(J14,L14,N14)) | Q14: =IF(I14="","",IF(I14>J14,1,0)+IF(K14>L14,1,0)+IF(M14="",0,IF(M14>N14,1,0))) | R14: =IF(I14="","",IF(J14>I14,1,0)+IF(L14>K14,1,0)+IF(M14="",0,IF(N14>M14,1,0))) | S14: =IF(I14="","",IF(Q14>R14,1,0)) | T14: =IF(I14="","",IF(R14>Q14,1,0)) | V14: =C14+C15 -> 0 | W14: =F14+F15 -> 0 | Y14: 7 | Z14: =VLOOKUP(CONCATENATE($D5," ",Y14),Setzlisten!$A:$E,5,0) -> #N/A | AA14: =VLOOKUP(CONCATENATE($D7," ",Y14),Setzlisten!$A:$E,5,0) -> #N/A | AB14: 7 | AD14: ↑ Zelle kopieren ↓ nur "Werte" unten einfügen
C15: =IF(D15="",0,VLOOKUP(D15,$Z8:$AB22,3,0)) -> 0 | F15: =IF(G15="",0,VLOOKUP(G15,$AA8:$AB22,2,0)) -> 0 | Y15: 8 | Z15: =VLOOKUP(CONCATENATE($D5," ",Y15),Setzlisten!$A:$E,5,0) -> #N/A | AA15: =VLOOKUP(CONCATENATE($D7," ",Y15),Setzlisten!$A:$E,5,0) -> #N/A | AB15: 8
A16: 3. Doppel 3rd Doubles | C16: =IF(D16="",0,VLOOKUP(D16,$Z8:$AB22,3,0)) -> 0 | F16: =IF(G16="",0,VLOOKUP(G16,$AA8:$AB22,2,0)) -> 0 | O16: =IF(I16="","",SUM(I16,K16,M16)) | P16: =IF(J16="","",SUM(J16,L16,N16)) | Q16: =IF(I16="","",IF(I16>J16,1,0)+IF(K16>L16,1,0)+IF(M16="",0,IF(M16>N16,1,0))) | R16: =IF(I16="","",IF(J16>I16,1,0)+IF(L16>K16,1,0)+IF(M16="",0,IF(N16>M16,1,0))) | S16: =IF(I16="","",IF(Q16>R16,1,0)) | T16: =IF(I16="","",IF(R16>Q16,1,0)) | V16: =C16+C17 -> 0 | W16: =F16+F17 -> 0 | Y16: 9 | Z16: =VLOOKUP(CONCATENATE($D5," ",Y16),Setzlisten!$A:$E,5,0) -> #N/A | AA16: =VLOOKUP(CONCATENATE($D7," ",Y16),Setzlisten!$A:$E,5,0) -> #N/A | AB16: 9
C17: =IF(D17="",0,VLOOKUP(D17,$Z8:$AB22,3,0)) -> 0 | F17: =IF(G17="",0,VLOOKUP(G17,$AA8:$AB22,2,0)) -> 0 | Y17: 10 | Z17: =VLOOKUP(CONCATENATE($D5," ",Y17),Setzlisten!$A:$E,5,0) -> #N/A | AA17: =VLOOKUP(CONCATENATE($D7," ",Y17),Setzlisten!$A:$E,5,0) -> #N/A | AB17: 10
A18: 1. Einzel 1st Singles | C18: =IF(D18="",0,VLOOKUP(D18,$Z8:$AB22,3,0)) -> 0 | F18: =IF(G18="",0,VLOOKUP(G18,$AA8:$AB22,2,0)) -> 0 | O18: =IF(I18="","",SUM(I18,K18,M18)) | P18: =IF(J18="","",SUM(J18,L18,N18)) | Q18: =IF(I18="","",IF(I18>J18,1,0)+IF(K18>L18,1,0)+IF(M18="",0,IF(M18>N18,1,0))) | R18: =IF(I18="","",IF(J18>I18,1,0)+IF(L18>K18,1,0)+IF(M18="",0,IF(N18>M18,1,0))) | S18: =IF(I18="","",IF(Q18>R18,1,0)) | T18: =IF(I18="","",IF(R18>Q18,1,0)) | V18: =C18 -> 0 | W18: =F18 -> 0 | Y18: 11 | Z18: =VLOOKUP(CONCATENATE($D5," ",Y18),Setzlisten!$A:$E,5,0) -> #N/A | AA18: =VLOOKUP(CONCATENATE($D7," ",Y18),Setzlisten!$A:$E,5,0) -> #N/A | AB18: 11
A19: 2. Einzel 2nd Singles | C19: =IF(D19="",0,VLOOKUP(D19,$Z8:$AB22,3,0)) -> 0 | F19: =IF(G19="",0,VLOOKUP(G19,$AA8:$AB22,2,0)) -> 0 | O19: =IF(I19="","",SUM(I19,K19,M19)) | P19: =IF(J19="","",SUM(J19,L19,N19)) | Q19: =IF(I19="","",IF(I19>J19,1,0)+IF(K19>L19,1,0)+IF(M19="",0,IF(M19>N19,1,0))) | R19: =IF(I19="","",IF(J19>I19,1,0)+IF(L19>K19,1,0)+IF(M19="",0,IF(N19>M19,1,0))) | S19: =IF(I19="","",IF(Q19>R19,1,0)) | T19: =IF(I19="","",IF(R19>Q19,1,0)) | V19: =C19 -> 0 | W19: =F19 -> 0 | Y19: 12 | Z19: =VLOOKUP(CONCATENATE($D5," ",Y19),Setzlisten!$A:$E,5,0) -> #N/A | AA19: =VLOOKUP(CONCATENATE($D7," ",Y19),Setzlisten!$A:$E,5,0) -> #N/A | AB19: 12
Y20: 13 | Z20: =VLOOKUP(CONCATENATE($D5," ",Y20),Setzlisten!$A:$E,5,0) -> #N/A | AA20: =VLOOKUP(CONCATENATE($D7," ",Y20),Setzlisten!$A:$E,5,0) -> #N/A | AB20: 13
A21: Ende (End): | C21: Sieger: Winner | E21: =IF(S21="","",IF(S21>T21,D5,D7)) | I21: Ergebnis: Result | O21: =IF(O12="","",SUM(O12:O19)) | P21: =IF(P12="","",SUM(P12:P19)) | Q21: =IF(Q12="","",SUM(Q12:Q19)) | R21: =IF(R12="","",SUM(R12:R19)) | S21: =IF(S12="","",SUM(S12:S19)) | T21: =IF(T12="","",SUM(T12:T19)) | Y21: 14 | Z21: =VLOOKUP(CONCATENATE($D5," ",Y21),Setzlisten!$A:$E,5,0) -> #N/A | AA21: =VLOOKUP(CONCATENATE($D7," ",Y21),Setzlisten!$A:$E,5,0) -> #N/A | AB21: 14
A22: =Allgemeines!H5 -> 0.64583333 | Y22: 15 | Z22: =VLOOKUP(CONCATENATE($D5," ",Y22),Setzlisten!$A:$E,5,0) -> #N/A | AA22: =VLOOKUP(CONCATENATE($D7," ",Y22),Setzlisten!$A:$E,5,0) -> #N/A | AB22: 15
D24: Besondere Vorkommnisse: Noteworthy Events
A26: Die Richtigkeit der Angaben wird bescheinigt. Das Spiel hat unter Beachtung der Spielordnung stattgefunden. The accuracy of the information is certified. The match took place in accordance with the League and Match Rules.
A27: =Allgemeines!$B$3 -> Hamburg | E27: =Allgemeines!$B$4 -> 46023
A29: Ort (Place) | E29: Datum (Date) | G29: Gruppenkoordinator:in | J29: Kapitän:in Heimverein | P29: Kapitän:in Gastverein
G30: Group Coordinator | J30: Captain Home Club | P30: Captain Guest Club
G31: =Allgemeines!$D$2 -> George Washington | J31: =IF(D5="","",VLOOKUP(D5,Allgemeines!$B$7:$D$12,3,0)) | P31: =IF(D7="","",VLOOKUP(D7,Allgemeines!$B$7:$D$12,3,0))
A32: Queere Badminton Liga | F32: =IF(V43>V45,CONCATENATE("Achtung! Teamreihenfolge ",D36," nicht richtig! 1. und 2. Doppel tauschen."),IF(V45>V47,CONCATENATE("Achtung! Teamreihenfolge ",D36," nicht richtig! 2. und 3. Doppel tauschen."),IF(AND(V49>=V50,V50>0),CONCATENATE("Achtung! Teamreihenfolge ",D36," nicht richtig! Beide Einzel tauschen."),IF(W43>W45,CONCATENATE("Achtung! Teamreihenfolge ",D38," nicht richtig! 1. und 2. Doppel tauschen."),IF(W45>W47,CONCATENATE("Achtung! Teamreihenfolge ",D38," nicht richtig! 2. und 3. Doppel tauschen."),IF(AND(W49>=W50,W50>0),CONCATENATE("Achtung! Teamreihenfolge ",D38," nicht richtig! Beide Einzel tauschen."),""))))))
A33: Spielberichtsbogen
A34: Match Report Sheet
A36: Heimteam: | L36: Gruppe: | M36: =Gruppe -> II
C37: Home team | L37: Group
A38: Gastteam: | J38: Austragungsort: | M38: =Austragungsort -> Sporthalle Berlin | Y38: Heimteam | AA38: Gastteam | AD38: Text für meinspielplan.de
C39: Guest team | L39: Venue | Y39: 1 | Z39: =VLOOKUP(CONCATENATE($D36," ",Y39),Setzlisten!$A:$E,5,0) -> #N/A | AA39: =VLOOKUP(CONCATENATE($D38," ",Y39),Setzlisten!$A:$E,5,0) -> #N/A | AB39: 1 | AD39: =CONCATENATE(A43,": ",D43," mit ",D44," - ",G43," mit ",G44,", ",I43,":",J43,", ",K43,":",L43,IF(M43="","",CONCATENATE(", ",M43,":",N43)),CHAR(10),A45,": ",D45," mit ",D46," - ",G45," mit ",G46,", ",I45,":",J45,", ",K45,":",L45,IF(M45="","",CONCATENATE(", ",M45,":",N45)),CHAR(10),A47,": ",D47," mit ",D48," - ",G47," mit ",G48,", ",I47,":",J47,", ",K47,":",L47,IF(M47="","",CONCATENATE(", ",M47,":",N47)),CHAR(10),A49,": ",D49," - ",G49,", ",I49,":",J49,", ",K49,":",L49,IF(M49="","",CONCATENATE(", ",M49,":",N49)),CHAR(10),A50,": ",D50," - ",G50,", ",I50,":",J50,", ",K50,":",L50,IF(M50="","",CONCATENATE(", ",M50,":",N50))) -> 1. Doppel 1st Doubles: mit - mit , :, : 2. Doppel 2nd Doubles: mit - mit , :, : 3. Doppel 3rd Doubles: mit - mit , :, : 1. Einzel 1st Singles: - , :, : 2. Einzel 2nd Singles: - , :, :
A40: Beginn: (Start) | C40: RL-Pos. | D40: Heimteam Home team | F40: RL-Pos. | G40: Gastteam Guest team | I40: 1. Satz 1st Game | K40: 2. Satz 2nd Game | M40: 3. Satz 3rd Game | O40: Punkte (Points) | Q40: Sätze (Games) | S40: Spiele (Matches) | V40: RL-Pos. Heim-team | W40: RL-Pos. Gast-team | Y40: 2 | Z40: =VLOOKUP(CONCATENATE($D36," ",Y40),Setzlisten!$A:$E,5,0) -> #N/A | AA40: =VLOOKUP(CONCATENATE($D38," ",Y40),Setzlisten!$A:$E,5,0) -> #N/A | AB40: 2
A41: =A10 -> 0.58333333 | O41: Heim Home | P41: Gast Guest | Q41: Heim Home | R41: Gast Guest | S41: Heim Home | T41: Gast Guest | Y41: 3 | Z41: =VLOOKUP(CONCATENATE($D36," ",Y41),Setzlisten!$A:$E,5,0) -> #N/A | AA41: =VLOOKUP(CONCATENATE($D38," ",Y41),Setzlisten!$A:$E,5,0) -> #N/A | AB41: 3
Y42: 4 | Z42: =VLOOKUP(CONCATENATE($D36," ",Y42),Setzlisten!$A:$E,5,0) -> #N/A | AA42: =VLOOKUP(CONCATENATE($D38," ",Y42),Setzlisten!$A:$E,5,0) -> #N/A | AB42: 4
A43: 1. Doppel 1st Doubles | C43: =IF(D43="",0,VLOOKUP(D43,$Z39:$AB53,3,0)) -> 0 | F43: =IF(G43="",0,VLOOKUP(G43,$AA39:$AB53,2,0)) -> 0 | O43: =IF(I43="","",SUM(I43,K43,M43)) | P43: =IF(J43="","",SUM(J43,L43,N43)) | Q43: =IF(I43="","",IF(I43>J43,1,0)+IF(K43>L43,1,0)+IF(M43="",0,IF(M43>N43,1,0))) | R43: =IF(I43="","",IF(J43>I43,1,0)+IF(L43>K43,1,0)+IF(M43="",0,IF(N43>M43,1,0))) | S43: =IF(I43="","",IF(Q43>R43,1,0)) | T43: =IF(I43="","",IF(R43>Q43,1,0)) | V43: =C43+C44 -> 0 | W43: =F43+F44 -> 0 | Y43: 5 | Z43: =VLOOKUP(CONCATENATE($D36," ",Y43),Setzlisten!$A:$E,5,0) -> #N/A | AA43: =VLOOKUP(CONCATENATE($D38," ",Y43),Setzlisten!$A:$E,5,0) -> #N/A | AB43: 5
C44: =IF(D44="",0,VLOOKUP(D44,$Z39:$AB53,3,0)) -> 0 | F44: =IF(G44="",0,VLOOKUP(G44,$AA39:$AB53,2,0)) -> 0 | Y44: 6 | Z44: =VLOOKUP(CONCATENATE($D36," ",Y44),Setzlisten!$A:$E,5,0) -> #N/A | AA44: =VLOOKUP(CONCATENATE($D38," ",Y44),Setzlisten!$A:$E,5,0) -> #N/A | AB44: 6
A45: 2. Doppel 2nd Doubles | C45: =IF(D45="",0,VLOOKUP(D45,$Z39:$AB53,3,0)) -> 0 | F45: =IF(G45="",0,VLOOKUP(G45,$AA39:$AB53,2,0)) -> 0 | O45: =IF(I45="","",SUM(I45,K45,M45)) | P45: =IF(J45="","",SUM(J45,L45,N45)) | Q45: =IF(I45="","",IF(I45>J45,1,0)+IF(K45>L45,1,0)+IF(M45="",0,IF(M45>N45,1,0))) | R45: =IF(I45="","",IF(J45>I45,1,0)+IF(L45>K45,1,0)+IF(M45="",0,IF(N45>M45,1,0))) | S45: =IF(I45="","",IF(Q45>R45,1,0)) | T45: =IF(I45="","",IF(R45>Q45,1,0)) | V45: =C45+C46 -> 0 | W45: =F45+F46 -> 0 | Y45: 7 | Z45: =VLOOKUP(CONCATENATE($D36," ",Y45),Setzlisten!$A:$E,5,0) -> #N/A | AA45: =VLOOKUP(CONCATENATE($D38," ",Y45),Setzlisten!$A:$E,5,0) -> #N/A | AB45: 7 | AD45: ↑ Zelle kopieren ↓ nur "Werte" unten einfügen
...

Sheet 5.Begegnung
A1: Queere Badminton Liga | F1: =IF(V12>V14,CONCATENATE("Achtung! Teamreihenfolge ",D5," nicht richtig! 1. und 2. Doppel tauschen."),IF(V14>V16,CONCATENATE("Achtung! Teamreihenfolge ",D5," nicht richtig! 2. und 3. Doppel tauschen."),IF(AND(V18>=V19,V19>0),CONCATENATE("Achtung! Teamreihenfolge ",D5," nicht richtig! Beide Einzel tauschen."),IF(W12>W14,CONCATENATE("Achtung! Teamreihenfolge ",D7," nicht richtig! 1. und 2. Doppel tauschen."),IF(W14>W16,CONCATENATE("Achtung! Teamreihenfolge ",D7," nicht richtig! 2. und 3. Doppel tauschen."),IF(AND(W18>=W19,W19>0),CONCATENATE("Achtung! Teamreihenfolge ",D7," nicht richtig! Beide Einzel tauschen."),""))))))
A2: Spielberichtsbogen
A3: Match Report Sheet
A5: Heimteam: | L5: Gruppe: | M5: =Gruppe -> II
C6: Home team | L6: Group
A7: Gastteam: | J7: Austragungsort: | M7: =Austragungsort -> Sporthalle Berlin | Y7: Heimteam | AA7: Gastteam | AD7: Text für meinspielplan.de
